在软件开发中，错误处理是构建健壮应用的关键一环。Rust 语言在这方面提供了与众不同的、更加安全和明确的机制，让错误处理变得更加优雅和可控。


## Result：处理可恢复的错误

Rust 中的 **`Result<T, E>`** 类型是一个枚举，它旨在表示一个操作可能成功或失败的结果。这与 Java 中使用 `try-catch` 块来捕获和处理异常类似，但 Rust 的 `Result` 将这种可能性直接编码在类型系统中，强制你在编译时就考虑并处理所有可能的结果。

`Result` 有两个变体：

  * **`Ok(T)`**：表示操作成功，并包含类型为 `T` 的成功值。
  * **`Err(E)`**：表示操作失败，并包含类型为 `E` 的错误信息。

这种设计使得错误处理变得异常明确。你不能仅仅忽略一个可能失败的操作，编译器会强制你处理 `Ok` 和 `Err` 两种情况。

### 示例：I/O 操作与 `match` 语句

文件 I/O 是一个常见的可能失败的操作。在 Rust 中，像 `fs::read_to_string` 这样的函数会返回一个 `Result`，因为它可能会因为文件不存在、权限不足等原因而失败。

```rust
use std::fs;
use std::io;

// read_file_content 函数返回 Result<String, io::Error>
fn read_file_content(path: &str) -> Result<String, io::Error> {
    fs::read_to_string(path)
}

fn main() {
    // 尝试读取一个存在的文件
    let existing_file_path = "hello.txt";

    // 使用 match 表达式处理 Result
    match read_file_content(existing_file_path) {
        Ok(content) => {
            println!("成功读取文件 '{}'：", existing_file_path);
            println!("{}", content);
        },
        Err(e) => {
            println!("读取文件 '{}' 失败：{}", existing_file_path, e);
        },
    }

    // 尝试读取一个不存在的文件
    let non_existing_file_path = "non_existent_file.txt";

    match read_file_content(non_existing_file_path) {
        Ok(content) => {
            println!("成功读取文件 '{}'：", non_existing_file_path);
            println!("{}", content);
        },
        Err(e) => {
            println!("读取文件 '{}' 失败：{}", non_existing_file_path, e);
        },
    }
}
```

在上述代码中，我们使用 `match` 语句对 `read_file_content` 返回的 `Result` 进行模式匹配。如果结果是 `Ok`，我们就解包出文件内容并打印；如果是 `Err`，我们就打印错误信息。这确保了每种可能性都得到了明确的处理。


## `?` 运算符：简化错误传播

为了进一步简化错误处理代码，Rust 引入了 **`?` 运算符**。这个语法糖非常强大，它可以在函数返回 `Result` 时自动传播错误，使代码更加简洁和流畅。

当你在一个 `Result` 值后面使用 `?` 运算符时：

  * 如果 `Result` 是 **`Err(E)`**，那么 `?` 会立即从当前函数中**返回这个错误**，就像 Java 中的 `throw` 语句一样。
  * 如果 `Result` 是 **`Ok(T)`**，那么 `?` 会将 `T` 值**解包**出来，并让程序继续执行。

让我们使用 `?` 运算符来改写 `read_file_content` 函数：

```rust
use std::fs;
use std::io; // 确保引入 io 模块

fn read_file_content_with_question_mark(path: &str) -> Result<String, io::Error> {
    // fs::read_to_string(path) 返回 Result<String, io::Error>
    // 使用 ? 运算符，如果读取失败，错误会立即从此函数返回
    let content = fs::read_to_string(path)?;
    // 如果上面一行没有返回错误，说明成功读取，此时返回 Ok(content)
    Ok(content)
}

fn main() {
    // 使用 read_file_content_with_question_mark 函数，调用方式不变
    let existing_file_path = "hello.txt";

    match read_file_content_with_question_mark(existing_file_path) {
        Ok(content) => {
            println!("成功读取文件 '{}'：", existing_file_path);
            println!("{}", content);
        },
        Err(e) => {
            println!("读取文件 '{}' 失败：{}", existing_file_path, e);
        },
    }
    // ... 对 non_existing_file_path 的处理与上面相同 ...
}
```

通过 `?` 运算符，`read_file_content_with_question_mark` 函数变得更加紧凑。它让你可以专注于成功的路径，而错误处理则被优雅地自动化。


## panic\!：不可恢复的程序崩溃

除了 `Result` 这种用于可恢复错误的机制外，Rust 还提供了一种处理**不可恢复错误**的方式，那就是 **`panic!`**。

`panic!` 在 Rust 中是一个宏，用于在运行时触发一个严重的错误，并导致程序的当前线程停止执行，最终可能导致整个程序终止。这与 Java 中那些\*\*未被 `try-catch` 捕获的运行时异常（例如 `NullPointerException` 或 `ArrayIndexOutOfBoundsException`）\*\*导致应用程序崩溃的行为非常相似。

### `panic!` 与 Java 中未捕获异常的类比

在 Java 中：

```java
public class JavaNPE {
    public static void main(String[] args) {
        String data = null;
        // 尝试对 null 对象调用方法，会抛出 NullPointerException
        System.out.println(data.length()); // 运行时抛出 NullPointerException
        System.out.println("This line will not be executed."); // 此行不会执行
    }
}
```

当 `data` 为 `null` 时，尝试调用 `data.length()` 会导致 `NullPointerException`。如果这个异常没有被任何 `try-catch` 块捕获，JVM 进程就会终止，程序“崩溃”。

在 Rust 中，`panic!` 的行为模式与此高度对应：

```rust
fn main() {
    let data: Option<String> = None; // 明确表示 data 可能没有值

    // 尝试对 None 值调用 unwrap()，会触发 panic!
    println!("Data length: {}", data.unwrap().len()); // 运行时 panic!
    println!("This line will not be executed."); // 此行不会执行
}
```

这里，`data` 是一个 `Option<String>` 类型，它被明确地设为 `None`（没有值）。当你尝试对其调用 `.unwrap()` 方法时，如果 `Option` 是 `None`，Rust 就会触发 `panic!`。这会导致程序像 Java 的未捕获 NPE 一样终止。

### `panic!` 的作用和行为

当 `panic!` 发生时：

1.  **停止当前线程**：程序的当前执行线程会立即停止。
2.  **栈回溯 (Unwinding)**：Rust 会沿着调用栈回溯，清理（释放）栈上所有的数据。
3.  **程序终止**：如果这个 `panic!` 没有被特殊的机制（如 `catch_unwind`，这通常用于库或 FFI 边界的特殊场景，不常用作常规业务逻辑的错误处理）捕获，**整个 Rust 程序进程就会终止**。

### `Result` vs. `panic!`: 区分可恢复与不可恢复

  * **`Result` 代表可恢复的错误**：这些错误是程序设计者**预期到可能发生**的，并且程序有能力通过备用逻辑、用户提示或重试机制来处理并从中恢复。例如，文件不存在、网络连接超时。
  * **`panic!` 代表不可恢复的错误**：这些错误通常意味着程序中存在一个 **Bug**，或者程序进入了一个**不应该发生的、无法安全继续执行的状态**。例如，逻辑错误导致的索引越界、对一个被认为是“必然存在”的值却发现它不存在（如 `Option::unwrap()` 了一个 `None`）。在这种情况下，Rust 的哲学是“快速失败”——立即中止程序，以防止潜在的数据损坏或更严重的、难以追踪的问题。这强制开发者去定位并修复这些底层的 Bug。

Rust 通过在 **编译时** 强制处理 `Result`，并在 **运行时** 通过 `panic!` 来暴露不可恢复的 Bug，从而大大提高了程序的健壮性和安全性，避免了 Java 中许多常见的运行时错误。